Workbook
Name kode_jawaban: DF!$D$33

Sheet XL-Test
A19: Intruksi
B21: Easy Level - Latihan Soal Excel Gaji dan Potongan
B23: Soal : | C23: Gunakan Fungsi Excel (Function) untuk menyelsaikan kasus dibawah ini, tidak disarankan menggunakan cara manual
B24: 1 | C24: Isi kolom Pokok berdasarkan pendidikan dari Tabel Gaji (Rp) yang ada pada Sheet Data
B25: 2 | C25: Isi kolom Tunjangan berdasarkan pendidikan dari Tabel Gaji (Rp) yang ada pada Sheet Data
B26: 3 | C26: Isi kolom Uang Makan berdasarkan pendidikan dari Tabel Gaji (Rp) yang ada pada Sheet Data. (Dalam 1 Bulan dihitung 25 hari kerja)
B27: 4 | C27: Kolom Total Gaji adalah jumlah dari gaji yang didapatkan dari penjumlahan Gaji pokok, Tunjangan dan Uang Makan
B28: 5 | C28: Isi kolom Pajak dengan jumlah Nilai pajak berdasarkan Pendidikan yang didapatkan dari Table Pajak
B29: 6 | C29: Isi kolom Gaji setelah pajak yang didapatkan dari Total Gaji dikurangi Pajak
B30: 7 | C30: Isi kolom Potongan Disiplin sesuai dengan Sanksi Disiplin yang didapatkan berdasarkan Table Potongan Hukuman dari Total Gaji
B31: 8 | C31: Isi kolom Potongan Waktu Kerja sesuai dengan Sanksi Jam yang didapatkan berdasarkan Table Potongan Waktu Kerja dari Total Gaji
B32: 9 | C32: Isi kolom Gaji Bersih yang didapatkan dari Gaji setelah pajak dikurangi potongan-potongan
B33: 10 | C33: Jumlahkan Total semua kolom, kecuali kolom Pajak. Pajak isi dengan Rata-rata (Tidak termasuk Contoh)
C35: Sudah selesai mengerjakan? kirim Kode Soal dan Kode Jawaban diatas ke alamat : https://belajarexcel.id/xl-test/jawaban untuk mengecek hasilnya
C36: atau klik tombol disamping
A42: DAFTAR GAJI PEGAWAI TIDAK TETAP (PER-BULAN)
A43: PADA BADAN KERJA INTERNASIONAL
F46: 1 | G46: 2 | H46: 3 | I46: 4 | J46: 5 | K46: 6 | L46: 7 | M46: 8 | N46: 9
A47: NO | B47: PENDIDIKAN | C47: NAMA PEGAWAI | D47: SANKSI | F47: GAJI (Rp.) | I47: TOTAL GAJI (Rp.) | J47: PAJAK (%) | K47: GAJI SETELAH PAJAK (Rp.) | L47: POT. DISIPLIN (Rp.) | M47: POT. WAKTU KERJA (Rp.) | N47: GAJI BERSIH (Rp.)
D48: DIS | E48: JAM | F48: POKOK | G48: TUNJANGAN | H48: UANG MAKAN
A49: Contoh | B49: S-1 | C49: Andi Setiadi | D49: R | E49: T2 | F49: 3500000 | G49: 1650000 | H49: 350000 | I49: 5500000 | J49: 0.04 | K49: 5280000 | L49: 825000 | M49: 275000 | N49: 4180000
A51: 1 | B51: D-III | C51: Gina Utami Andi | D51: N | E51: T5 | F51: =VLOOKUP(B51,DATA!$F$3:$I$7,2,) -> 3200000 | G51: =VLOOKUP(B51,DATA!$F$3:$I$7,3,) -> 1350000 | H51: =VLOOKUP(B51,DATA!$F$3:$I$7,4,) -> 13000 | I51: ='XL-Test'!F51+'XL-Test'!G51+'XL-Test'!H51 -> 4563000 | J51: =HLOOKUP(B51,DATA!$F$11:$J$12,2,) -> 0.03 | K51: =I51-(I51*J51) -> 4426110 | L51: =VLOOKUP(D51,DATA!$C$3:$D$7,2,)*I51 -> 0 | M51: =_xlfn.XLOOKUP(E51,DATA!$D$11:$D$16,DATA!$C$11:$C$16)*I51 -> 1140750 | N51: =K51-L51-M51 -> 3285360
A52: 2 | B52: S-1 | C52: Agung Perkasa | D52: N | E52: T2 | F52: =VLOOKUP(B52,DATA!$F$3:$I$7,2,) -> 3500000 | G52: =VLOOKUP(B52,DATA!$F$3:$I$7,3,) -> 1650000 | H52: =VLOOKUP(B52,DATA!$F$3:$I$7,4,) -> 14000 | I52: ='XL-Test'!F52+'XL-Test'!G52+'XL-Test'!H52 -> 5164000 | J52: =HLOOKUP(B52,DATA!$F$11:$J$12,2,) -> 0.04 | K52: =I52-(I52*J52) -> 4957440 | L52: =VLOOKUP(D52,DATA!$C$3:$D$7,2,)*I52 -> 0 | M52: =_xlfn.XLOOKUP(E52,DATA!$D$11:$D$16,DATA!$C$11:$C$16)*I52 -> 258200 | N52: =K52-L52-M52 -> 4699240
A53: 3 | B53: SMA | C53: Kaludin amat | D53: R | E53: T5 | F53: =VLOOKUP(B53,DATA!$F$3:$I$7,2,) -> 3000000 | G53: =VLOOKUP(B53,DATA!$F$3:$I$7,3,) -> 1150000 | H53: =VLOOKUP(B53,DATA!$F$3:$I$7,4,) -> 12000 | I53: ='XL-Test'!F53+'XL-Test'!G53+'XL-Test'!H53 -> 4162000 | J53: =HLOOKUP(B53,DATA!$F$11:$J$12,2,) -> 0.02 | K53: =I53-(I53*J53) -> 4078760 | L53: =VLOOKUP(D53,DATA!$C$3:$D$7,2,)*I53 -> 624300 | M53: =_xlfn.XLOOKUP(E53,DATA!$D$11:$D$16,DATA!$C$11:$C$16)*I53 -> 1040500 | N53: =K53-L53-M53 -> 2413960
A54: 4 | B54: S-2 | C54: Lina Syahputra Joko | D54: N | E54: T1 | F54: =VLOOKUP(B54,DATA!$F$3:$I$7,2,) -> 3850000 | G54: =VLOOKUP(B54,DATA!$F$3:$I$7,3,) -> 1850000 | H54: =VLOOKUP(B54,DATA!$F$3:$I$7,4,) -> 15000 | I54: ='XL-Test'!F54+'XL-Test'!G54+'XL-Test'!H54 -> 5715000 | J54: =HLOOKUP(B54,DATA!$F$11:$J$12,2,) -> 0.05 | K54: =I54-(I54*J54) -> 5429250 | L54: =VLOOKUP(D54,DATA!$C$3:$D$7,2,)*I54 -> 0 | M54: =_xlfn.XLOOKUP(E54,DATA!$D$11:$D$16,DATA!$C$11:$C$16)*I54 -> 0 | N54: =K54-L54-M54 -> 5429250
A55: 5 | B55: S-1 | C55: Kiki Fajar Eka | D55: B | E55: T4 | F55: =VLOOKUP(B55,DATA!$F$3:$I$7,2,) -> 3500000 | G55: =VLOOKUP(B55,DATA!$F$3:$I$7,3,) -> 1650000 | H55: =VLOOKUP(B55,DATA!$F$3:$I$7,4,) -> 14000 | I55: ='XL-Test'!F55+'XL-Test'!G55+'XL-Test'!H55 -> 5164000 | J55: =HLOOKUP(B55,DATA!$F$11:$J$12,2,) -> 0.04 | K55: =I55-(I55*J55) -> 4957440 | L55: =VLOOKUP(D55,DATA!$C$3:$D$7,2,)*I55 -> 2582000 | M55: =_xlfn.XLOOKUP(E55,DATA!$D$11:$D$16,DATA!$C$11:$C$16)*I55 -> 774600 | N55: =K55-L55-M55 -> 1600840
A56: 6 | B56: SMA | C56: Gina Anggraini Halim | D56: N | E56: T1 | F56: =VLOOKUP(B56,DATA!$F$3:$I$7,2,) -> 3000000 | G56: =VLOOKUP(B56,DATA!$F$3:$I$7,3,) -> 1150000 | H56: =VLOOKUP(B56,DATA!$F$3:$I$7,4,) -> 12000 | I56: ='XL-Test'!F56+'XL-Test'!G56+'XL-Test'!H56 -> 4162000 | J56: =HLOOKUP(B56,DATA!$F$11:$J$12,2,) -> 0.02 | K56: =I56-(I56*J56) -> 4078760 | L56: =VLOOKUP(D56,DATA!$C$3:$D$7,2,)*I56 -> 0 | M56: =_xlfn.XLOOKUP(E56,DATA!$D$11:$D$16,DATA!$C$11:$C$16)*I56 -> 0 | N56: =K56-L56-M56 -> 4078760
A57: 7 | B57: S-1 | C57: Wibowo Rian Hartono | D57: N | E57: T3 | F57: =VLOOKUP(B57,DATA!$F$3:$I$7,2,) -> 3500000 | G57: =VLOOKUP(B57,DATA!$F$3:$I$7,3,) -> 1650000 | H57: =VLOOKUP(B57,DATA!$F$3:$I$7,4,) -> 14000 | I57: ='XL-Test'!F57+'XL-Test'!G57+'XL-Test'!H57 -> 5164000 | J57: =HLOOKUP(B57,DATA!$F$11:$J$12,2,) -> 0.04 | K57: =I57-(I57*J57) -> 4957440 | L57: =VLOOKUP(D57,DATA!$C$3:$D$7,2,)*I57 -> 0 | M57: =_xlfn.XLOOKUP(E57,DATA!$D$11:$D$16,DATA!$C$11:$C$16)*I57 -> 516400 | N57: =K57-L57-M57 -> 4441040
A58: 8 | B58: S-2 | C58: Putri Tono | D58: S | E58: T2 | F58: =VLOOKUP(B58,DATA!$F$3:$I$7,2,) -> 3850000 | G58: =VLOOKUP(B58,DATA!$F$3:$I$7,3,) -> 1850000 | H58: =VLOOKUP(B58,DATA!$F$3:$I$7,4,) -> 15000 | I58: ='XL-Test'!F58+'XL-Test'!G58+'XL-Test'!H58 -> 5715000 | J58: =HLOOKUP(B58,DATA!$F$11:$J$12,2,) -> 0.05 | K58: =I58-(I58*J58) -> 5429250 | L58: =VLOOKUP(D58,DATA!$C$3:$D$7,2,)*I58 -> 1428750 | M58: =_xlfn.XLOOKUP(E58,DATA!$D$11:$D$16,DATA!$C$11:$C$16)*I58 -> 285750 | N58: =K58-L58-M58 -> 3714750
A59: 9 | B59: S-2 | C59: Oka Halim Syahputra | D59: N | E59: T1 | F59: =VLOOKUP(B59,DATA!$F$3:$I$7,2,) -> 3850000 | G59: =VLOOKUP(B59,DATA!$F$3:$I$7,3,) -> 1850000 | H59: =VLOOKUP(B59,DATA!$F$3:$I$7,4,) -> 15000 | I59: ='XL-Test'!F59+'XL-Test'!G59+'XL-Test'!H59 -> 5715000 | J59: =HLOOKUP(B59,DATA!$F$11:$J$12,2,) -> 0.05 | K59: =I59-(I59*J59) -> 5429250 | L59: =VLOOKUP(D59,DATA!$C$3:$D$7,2,)*I59 -> 0 | M59: =_xlfn.XLOOKUP(E59,DATA!$D$11:$D$16,DATA!$C$11:$C$16)*I59 -> 0 | N59: =K59-L59-M59 -> 5429250
A60: 10 | B60: S-2 | C60: Fajar Lina Syahputra | D60: R | E60: T2 | F60: =VLOOKUP(B60,DATA!$F$3:$I$7,2,) -> 3850000 | G60: =VLOOKUP(B60,DATA!$F$3:$I$7,3,) -> 1850000 | H60: =VLOOKUP(B60,DATA!$F$3:$I$7,4,) -> 15000 | I60: ='XL-Test'!F60+'XL-Test'!G60+'XL-Test'!H60 -> 5715000 | J60: =HLOOKUP(B60,DATA!$F$11:$J$12,2,) -> 0.05 | K60: =I60-(I60*J60) -> 5429250 | L60: =VLOOKUP(D60,DATA!$C$3:$D$7,2,)*I60 -> 857250 | M60: =_xlfn.XLOOKUP(E60,DATA!$D$11:$D$16,DATA!$C$11:$C$16)*I60 -> 285750 | N60: =K60-L60-M60 -> 4286250
A61: 11 | B61: SMA | C61: Kiki Permata Eka | D61: R | E61: T1 | F61: =VLOOKUP(B61,DATA!$F$3:$I$7,2,) -> 3000000 | G61: =VLOOKUP(B61,DATA!$F$3:$I$7,3,) -> 1150000 | H61: =VLOOKUP(B61,DATA!$F$3:$I$7,4,) -> 12000 | I61: ='XL-Test'!F61+'XL-Test'!G61+'XL-Test'!H61 -> 4162000 | J61: =HLOOKUP(B61,DATA!$F$11:$J$12,2,) -> 0.02 | K61: =I61-(I61*J61) -> 4078760 | L61: =VLOOKUP(D61,DATA!$C$3:$D$7,2,)*I61 -> 624300 | M61: =_xlfn.XLOOKUP(E61,DATA!$D$11:$D$16,DATA!$C$11:$C$16)*I61 -> 0 | N61: =K61-L61-M61 -> 3454460
A62: 12 | B62: S-1 | C62: Sawidi Aisah | D62: S | E62: T3 | F62: =VLOOKUP(B62,DATA!$F$3:$I$7,2,) -> 3500000 | G62: =VLOOKUP(B62,DATA!$F$3:$I$7,3,) -> 1650000 | H62: =VLOOKUP(B62,DATA!$F$3:$I$7,4,) -> 14000 | I62: ='XL-Test'!F62+'XL-Test'!G62+'XL-Test'!H62 -> 5164000 | J62: =HLOOKUP(B62,DATA!$F$11:$J$12,2,) -> 0.04 | K62: =I62-(I62*J62) -> 4957440 | L62: =VLOOKUP(D62,DATA!$C$3:$D$7,2,)*I62 -> 1291000 | M62: =_xlfn.XLOOKUP(E62,DATA!$D$11:$D$16,DATA!$C$11:$C$16)*I62 -> 516400 | N62: =K62-L62-M62 -> 3150040
... A73: 23 | B73: S-1 | C73: Mira Hartono | D73: N | E73: T1 | F73: =VLOOKUP(B73,DATA!$F$3:$I$7,2,) -> 3500000 | G73: =VLOOKUP(B73,DATA!$F$3:$I$7,3,) -> 1650000 | H73: =VLOOKUP(B73,DATA!$F$3:$I$7,4,) -> 14000 | I73: ='XL-Test'!F73+'XL-Test'!G73+'XL-Test'!H73 -> 5164000 | J73: =HLOOKUP(B73,DATA!$F$11:$J$12,2,) -> 0.04 | K73: =I73-(I73*J73) -> 4957440 | L73: =VLOOKUP(D73,DATA!$C$3:$D$7,2,)*I73 -> 0 | M73: =_xlfn.XLOOKUP(E73,DATA!$D$11:$D$16,DATA!$C$11:$C$16)*I73 -> 0 | N73: =K73-L73-M73 -> 4957440
B74: 10 | C74: TOTAL | F74: =SUM(F51:F73) -> 79350000 | G74: =SUM(G51:G73) -> 35750000 | H74: =SUM(H51:H73) -> 315000 | I74: =SUM(I51:I73) -> 115415000 | J74: =AVERAGE(J51:J73) -> 0.036956522 | K74: =SUM(K51:K73) -> 110989050 | L74: =SUM(L51:L73) -> 12955000 | M74: =SUM(M51:M73) -> 8801750 | N74: =SUM(N51:N73) -> 89232300

Sheet DATA
B2: T. POTONGAN HUKUMAN | F2: TABEL GAJI (Rp.)
B3: DISIPLIN | C3: KET | D3: POTONGAN | F3: PENDIDIKAN | G3: POKOK | H3: TUNJANGAN | I3: UANG MAKAN / HARI
B4: Berat | C4: B | D4: 0.5 | F4: SMA | G4: 3000000 | H4: 1150000 | I4: 12000
B5: Sedang | C5: S | D5: 0.25 | F5: D-III | G5: 3200000 | H5: 1350000 | I5: 13000
B6: Ringan | C6: R | D6: 0.15 | F6: S-1 | G6: 3500000 | H6: 1650000 | I6: 14000
B7: Nihil | C7: N | D7: 0 | F7: S-2 | G7: 3850000 | H7: 1850000 | I7: 15000
B10: T. POTONGAN WAKTU KERJA | F10: TABEL PAJAK
B11: MENIT | C11: POT | D11: KET | F11: PENDIDIKAN | G11: SMA | H11: D-III | I11: S-1 | J11: S-2
B12: 0' | C12: 0 | D12: T1 | F12: PAJAK | G12: 0.02 | H12: 0.03 | I12: 0.04 | J12: 0.05
B13: 1' - 60' | C13: 0.05 | D13: T2
B14: 61' - 120' | C14: 0.1 | D14: T3
B15: 121' - 240' | C15: 0.15 | D15: T4
B16: 241' Keatas | C16: 0.25 | D16: T5

Sheet About
I6: XL-TEST adalah platform inovatif yang menyediakan latihan Excel interaktif dengan pemeriksaan otomatis,
I7: sehingga pengguna dapat langsung mengetahui jawaban yang benar maupun salah.
I10: Terdapat 5 Level soal :
J12: Easy Level | L12: (⭐)
J13: Medium Level | L13: (⭐⭐)
J14: Hard Level | L14: (⭐⭐⭐)
J15: Extreme Level | L15: (⭐⭐⭐⭐)
J16: Championship Level | L16: (⭐⭐⭐⭐⭐)
B17: Saya adalah seorang Excel Holic yang percaya bahwa setiap angka memiliki cerita yang bisa ditemukan dengan cara yang tepat. | I17: Free Access
B18: “Excel bukan cuma soal kerjaan tapi juga hobi yang aku nikmati.” | I18: https://belajarexcel.id/xl-test/
B19: Contact :
B20: 🌐 Web | C20: https://setiadi.me
B21: 🪡threads | C21: https://www.threads.com/@andisetiadi
D27: Perlu Video Penjelasan atau Kunci Jawaban ?
D28: Scan barcode atau kunjungi
D29: https://lynk.id/setiadi/page/jawaban-xl-test

Sheet DF
A1: DEF | D1: 1 | E1: 2 | F1: 3 | G1: 4 | H1: 5 | I1: 6 | J1: 7 | K1: 8 | L1: 9 | M1: 10 | W1: 1 | X1: 2 | Y1: 3 | Z1: 4 | AA1: 5 | AB1: 6 | AC1: 7 | AD1: 8 | AE1: 9 | AF1: 10
A2: EK6 | C2: 1 | D2: ='XL-Test'!F51 -> 3200000 | E2: ='XL-Test'!G51 -> 1350000 | F2: ='XL-Test'!H51 -> 13000 | G2: ='XL-Test'!I51 -> 4563000 | H2: ='XL-Test'!J51 -> 0.03 | I2: ='XL-Test'!K51 -> 4426110 | J2: ='XL-Test'!L51 -> 0 | K2: ='XL-Test'!M51 -> 1140750 | L2: ='XL-Test'!N51 -> 3285360 | M2: ='XL-Test'!F74 -> 79350000 | V2: 1 | W2: =_xlfn.FORMULATEXT('XL-Test'!F51) -> =VLOOKUP(B51,DATA!$F$3:$I$7,2,) | X2: =_xlfn.FORMULATEXT('XL-Test'!G51) -> =VLOOKUP(B51,DATA!$F$3:$I$7,3,) | Y2: =_xlfn.FORMULATEXT('XL-Test'!H51) -> =VLOOKUP(B51,DATA!$F$3:$I$7,4,) | Z2: =_xlfn.FORMULATEXT('XL-Test'!I51) -> ='XL-Test'!F51+'XL-Test'!G51+'XL-Test'!H51 | AA2: =_xlfn.FORMULATEXT('XL-Test'!J51) -> =HLOOKUP(B51,DATA!$F$11:$J$12,2,) | AB2: =_xlfn.FORMULATEXT('XL-Test'!K51) -> =I51-(I51*J51) | AC2: =_xlfn.FORMULATEXT('XL-Test'!L51) -> =VLOOKUP(D51,DATA!$C$3:$D$7,2,)*I51 | AD2: =_xlfn.FORMULATEXT('XL-Test'!M51) -> =XLOOKUP(E51,DATA!$D$11:$D$16,DATA!$C$11:$C$16)*I51 | AE2: =_xlfn.FORMULATEXT('XL-Test'!N51) -> =K51-L51-M51
C3: 2 | D3: ='XL-Test'!F54 -> 3850000 | E3: ='XL-Test'!G54 -> 1850000 | F3: ='XL-Test'!H54 -> 15000 | G3: ='XL-Test'!I54 -> 5715000 | H3: ='XL-Test'!J54 -> 0.05 | I3: ='XL-Test'!K54 -> 5429250 | J3: ='XL-Test'!L54 -> 0 | K3: ='XL-Test'!M54 -> 0 | L3: ='XL-Test'!N54 -> 5429250 | M3: ='XL-Test'!G74 -> 35750000 | V3: 2 | W3: =_xlfn.FORMULATEXT('XL-Test'!G51) -> =VLOOKUP(B51,DATA!$F$3:$I$7,3,)
C4: 3 | D4: ='XL-Test'!F58 -> 3850000 | E4: ='XL-Test'!G58 -> 1850000 | F4: ='XL-Test'!H58 -> 15000 | G4: ='XL-Test'!I58 -> 5715000 | H4: ='XL-Test'!J58 -> 0.05 | I4: ='XL-Test'!K58 -> 5429250 | J4: ='XL-Test'!L58 -> 1428750 | K4: ='XL-Test'!M58 -> 285750 | L4: ='XL-Test'!N58 -> 3714750 | M4: ='XL-Test'!H74 -> 315000 | V4: 3 | W4: =_xlfn.FORMULATEXT('XL-Test'!H51) -> =VLOOKUP(B51,DATA!$F$3:$I$7,4,)
C5: 4 | D5: ='XL-Test'!F60 -> 3850000 | E5: ='XL-Test'!G60 -> 1850000 | F5: ='XL-Test'!H60 -> 15000 | G5: ='XL-Test'!I60 -> 5715000 | H5: ='XL-Test'!J60 -> 0.05 | I5: ='XL-Test'!K60 -> 5429250 | J5: ='XL-Test'!L60 -> 857250 | K5: ='XL-Test'!M60 -> 285750 | L5: ='XL-Test'!N60 -> 4286250 | M5: ='XL-Test'!I74 -> 115415000 | V5: 4 | W5: =_xlfn.FORMULATEXT('XL-Test'!I51) -> ='XL-Test'!F51+'XL-Test'!G51+'XL-Test'!H51
C6: 5 | D6: ='XL-Test'!F61 -> 3000000 | E6: ='XL-Test'!G61 -> 1150000 | F6: ='XL-Test'!H61 -> 12000 | G6: ='XL-Test'!I61 -> 4162000 | H6: ='XL-Test'!J61 -> 0.02 | I6: ='XL-Test'!K61 -> 4078760 | J6: ='XL-Test'!L61 -> 624300 | K6: ='XL-Test'!M61 -> 0 | L6: ='XL-Test'!N61 -> 3454460 | M6: ='XL-Test'!J74 -> 0.036956522 | V6: 5 | W6: =_xlfn.FORMULATEXT('XL-Test'!J51) -> =HLOOKUP(B51,DATA!$F$11:$J$12,2,)
C7: 6 | D7: ='XL-Test'!F64 -> 3500000 | E7: ='XL-Test'!G64 -> 1650000 | F7: ='XL-Test'!H64 -> 14000 | G7: ='XL-Test'!I64 -> 5164000 | H7: ='XL-Test'!J64 -> 0.04 | I7: ='XL-Test'!K64 -> 4957440 | J7: ='XL-Test'!L64 -> 1291000 | K7: ='XL-Test'!M64 -> 258200 | L7: ='XL-Test'!N64 -> 3408240 | M7: ='XL-Test'!K74 -> 110989050 | V7: 6 | W7: =_xlfn.FORMULATEXT('XL-Test'!K51) -> =I51-(I51*J51)
C8: 7 | D8: ='XL-Test'!F65 -> 3200000 | E8: ='XL-Test'!G65 -> 1350000 | F8: ='XL-Test'!H65 -> 13000 | G8: ='XL-Test'!I65 -> 4563000 | H8: ='XL-Test'!J65 -> 0.03 | I8: ='XL-Test'!K65 -> 4426110 | J8: ='XL-Test'!L65 -> 0 | K8: ='XL-Test'!M65 -> 684450 | L8: ='XL-Test'!N65 -> 3741660 | M8: ='XL-Test'!L74 -> 12955000 | V8: 7 | W8: =_xlfn.FORMULATEXT('XL-Test'!L51) -> =VLOOKUP(D51,DATA!$C$3:$D$7,2,)*I51
C9: 8 | D9: ='XL-Test'!F69 -> 3500000 | E9: ='XL-Test'!G69 -> 1650000 | F9: ='XL-Test'!H69 -> 14000 | G9: ='XL-Test'!I69 -> 5164000 | H9: ='XL-Test'!J69 -> 0.04 | I9: ='XL-Test'!K69 -> 4957440 | J9: ='XL-Test'!L69 -> 0 | K9: ='XL-Test'!M69 -> 0 | L9: ='XL-Test'!N69 -> 4957440 | M9: ='XL-Test'!M74 -> 8801750 | V9: 8 | W9: =_xlfn.FORMULATEXT('XL-Test'!M51) -> =XLOOKUP(E51,DATA!$D$11:$D$16,DATA!$C$11:$C$16)*I51
C10: 9 | D10: ='XL-Test'!F71 -> 3850000 | E10: ='XL-Test'!G71 -> 1850000 | F10: ='XL-Test'!H71 -> 15000 | G10: ='XL-Test'!I71 -> 5715000 | H10: ='XL-Test'!J71 -> 0.05 | I10: ='XL-Test'!K71 -> 5429250 | J10: ='XL-Test'!L71 -> 2857500 | K10: ='XL-Test'!M71 -> 1428750 | L10: ='XL-Test'!N71 -> 1143000 | M10: ='XL-Test'!N74 -> 89232300 | V10: 9 | W10: =_xlfn.FORMULATEXT('XL-Test'!N51) -> =K51-L51-M51
C11: 10 | D11: ='XL-Test'!F73 -> 3500000 | E11: ='XL-Test'!G73 -> 1650000 | F11: ='XL-Test'!H73 -> 14000 | G11: ='XL-Test'!I73 -> 5164000 | H11: ='XL-Test'!J73 -> 0.04 | I11: ='XL-Test'!K73 -> 4957440 | J11: ='XL-Test'!L73 -> 0 | K11: ='XL-Test'!M73 -> 0 | L11: ='XL-Test'!N73 -> 4957440 | V11: 10
D12: =SUM('XL-Test'!F51:F73) -> 79350000 | E12: =SUM('XL-Test'!G51:G73) -> 35750000 | F12: =SUM('XL-Test'!H51:H73) -> 315000 | G12: =SUM('XL-Test'!I51:I73) -> 115415000 | H12: =SUM('XL-Test'!J51:J73) -> 0.85 | I12: =SUM('XL-Test'!K51:K73) -> 110989050 | J12: =SUM('XL-Test'!L51:L73) -> 12955000 | K12: =SUM('XL-Test'!M51:M73) -> 8801750 | L12: =SUM('XL-Test'!N51:N73) -> 89232300 | M12: =SUM('XL-Test'!F74:N74) -> 4.528081e+08 | T12: =ISNUMBER(FIND("SUM",W12)) -> TRUE | U12: =AND(ISNUMBER(FIND("=",W12)),ISNUMBER(FIND("(",W12)),ISNUMBER(FIND(":",W12))) -> TRUE | V12: 1 | W12: =_xlfn.FORMULATEXT('XL-Test'!F74) -> =SUM(F51:F73)
D13: =SUM(D2:D12) -> 114650000 | E13: =SUM(E2:E12) -> 51950000 | F13: =SUM(F2:F12) -> 455000 | G13: =SUM(G2:G12) -> 167055000 | H13: =SUM(H2:H12) -> 1.25 | I13: =SUM(I2:I12) -> 160509350 | J13: =SUM(J2:J12) -> 20013800 | K13: =SUM(K2:K12) -> 12885400 | ... M13: =SUM(M2:M12) -> 9.056162e+08 | T13: =ISNUMBER(FIND("SUM",W13)) -> TRUE | U13: =AND(ISNUMBER(FIND("=",W13)),ISNUMBER(FIND("(",W13)),ISNUMBER(FIND(":",W13))) -> TRUE | V13: 2 | W13: =_xlfn.FORMULATEXT('XL-Test'!G74) -> =SUM(G51:G73)
T14: =ISNUMBER(FIND("SUM",W14)) -> TRUE | U14: =AND(ISNUMBER(FIND("=",W14)),ISNUMBER(FIND("(",W14)),ISNUMBER(FIND(":",W14))) -> TRUE | V14: 3 | W14: =_xlfn.FORMULATEXT('XL-Test'!H74) -> =SUM(H51:H73)
C15: V | D15: =D13/1000 -> 114650 | E15: =E13/1000 -> 51950 | F15: =F13/1000 -> 455 | G15: =G13/1000 -> 167055 | H15: =H13*1000 -> 1250 | I15: =I13/1000 -> 160509.35 | J15: =J13/100 -> 200138 | K15: =K13/100 -> 128854 | L15: =L13/100 -> 1276101.5 | M15: =INT(SUM(M2:M5,M7:M12)/100+(M6*1000)+LEFT(M8,4)+LEFT(M9,4)+LEFT(M10,4)) -> 9075217 | T15: =ISNUMBER(FIND("SUM",W15)) -> TRUE | U15: =AND(ISNUMBER(FIND("=",W15)),ISNUMBER(FIND("(",W15)),ISNUMBER(FIND(":",W15))) -> TRUE | V15: 4 | W15: =_xlfn.FORMULATEXT('XL-Test'!I74) -> =SUM(I51:I73)
B16: =DEC2HEX(D15) -> 1BFDA | D16: =IFERROR(DEC2HEX(IF(AND(OR(D2=0,D2=""),NOT(D22)),D17,D15)),"EEEE") -> 1BFDA | E16: =IFERROR(DEC2HEX(IF(AND(OR(E2=0,E2=""),NOT(E22)),E17,E15)),"EEEE") -> CAEE | F16: =IFERROR(DEC2HEX(IF(AND(OR(F2=0,F2=""),NOT(F22)),F17,F15)),"EEEE") -> 1C7 | G16: =IFERROR(DEC2HEX(IF(AND(OR(G2=0,G2=""),NOT(G22)),G17,G15)),"EEEE") -> 28C8F | H16: =IFERROR(DEC2HEX(IF(AND(OR(H2=0,H2=""),NOT(H22)),H17,H15)),"EEEE") -> 4E2 | I16: =IFERROR(DEC2HEX(IF(AND(OR(I2=0,I2=""),NOT(I22)),I17,I15)),"EEEE") -> 272FD | J16: =IFERROR(DEC2HEX(IF(AND(OR(J2=0,J2=""),NOT(J22)),J17,J15)),"EEEE") -> 30DCA | K16: =IFERROR(DEC2HEX(IF(AND(OR(K2=0,K2=""),NOT(K22)),K17,K15)),"EEEE") -> 1F756 | ... M16: =IFERROR(DEC2HEX(IF(AND(OR(M2=0,M2=""),NOT(M22)),M17,M15)),"EEEE") -> 8A7A11 | T16: =ISNUMBER(FIND("AVE",W16)) -> TRUE | U16: =AND(ISNUMBER(FIND("=",W16)),ISNUMBER(FIND("(",W16)),ISNUMBER(FIND(":",W16))) -> TRUE | V16: 5 | W16: =_xlfn.FORMULATEXT('XL-Test'!J74) -> =AVERAGE(J51:J73)
B17: =DEC2HEX(D17) -> 2F1D | C17: Rand | D17: 12061 | E17: 94879 | F17: 87032 | G17: 11186 | H17: 76391 | I17: 59777 | J17: 13855 | K17: 67307 | L17: 47761 | M17: 52661 | T17: =ISNUMBER(FIND("SUM",W17)) -> TRUE | U17: =AND(ISNUMBER(FIND("=",W17)),ISNUMBER(FIND("(",W17)),ISNUMBER(FIND(":",W17))) -> TRUE | V17: 6 | W17: =_xlfn.FORMULATEXT('XL-Test'!K74) -> =SUM(K51:K73)
T18: =ISNUMBER(FIND("SUM",W18)) -> TRUE | U18: =AND(ISNUMBER(FIND("=",W18)),ISNUMBER(FIND("(",W18)),ISNUMBER(FIND(":",W18))) -> TRUE | V18: 7 | W18: =_xlfn.FORMULATEXT('XL-Test'!L74) -> =SUM(L51:L73)
C19: TRUE | D19: =DEC2HEX(HEX2DEC(LEFT(DEC2HEX(D17),2))+COLUMN()) -> 33 | E19: =DEC2HEX(HEX2DEC(LEFT(DEC2HEX(E17),2))+COLUMN()) -> 1C | F19: =DEC2HEX(HEX2DEC(LEFT(DEC2HEX(F17),2))+COLUMN()) -> 1B | G19: =DEC2HEX(HEX2DEC(LEFT(DEC2HEX(G17),2))+COLUMN()) -> 32 | H19: =DEC2HEX(HEX2DEC(LEFT(DEC2HEX(H17),2))+COLUMN()) -> 1A | I19: =DEC2HEX(HEX2DEC(LEFT(DEC2HEX(I17),2))+COLUMN()) -> F2 | J19: =DEC2HEX(HEX2DEC(LEFT(DEC2HEX(J17),2))+COLUMN()) -> 40 | K19: =DEC2HEX(HEX2DEC(LEFT(DEC2HEX(K17),2))+COLUMN()) -> 1B | ... M19: =DEC2HEX(HEX2DEC(LEFT(DEC2HEX(M17),2))+COLUMN()) -> DA | T19: =ISNUMBER(FIND("SUM",W19)) -> TRUE | U19: =AND(ISNUMBER(FIND("=",W19)),ISNUMBER(FIND("(",W19)),ISNUMBER(FIND(":",W19))) -> TRUE | V19: 8 | W19: =_xlfn.FORMULATEXT('XL-Test'!M74) -> =SUM(M51:M73)
C20: FALSE | D20: =DEC2HEX(HEX2DEC(RIGHT(DEC2HEX(D17),2))+COLUMN()) -> 21 | E20: =DEC2HEX(HEX2DEC(RIGHT(DEC2HEX(E17),2))+COLUMN()) -> A4 | F20: =DEC2HEX(HEX2DEC(RIGHT(DEC2HEX(F17),2))+COLUMN()) -> FE | G20: =DEC2HEX(HEX2DEC(RIGHT(DEC2HEX(G17),2))+COLUMN()) -> B9 | H20: =DEC2HEX(HEX2DEC(RIGHT(DEC2HEX(H17),2))+COLUMN()) -> 6F | I20: =DEC2HEX(HEX2DEC(RIGHT(DEC2HEX(I17),2))+COLUMN()) -> 8A | J20: =DEC2HEX(HEX2DEC(RIGHT(DEC2HEX(J17),2))+COLUMN()) -> 29 | K20: =DEC2HEX(HEX2DEC(RIGHT(DEC2HEX(K17),2))+COLUMN()) -> F6 | ... M20: =DEC2HEX(HEX2DEC(RIGHT(DEC2HEX(M17),2))+COLUMN()) -> C2 | T20: =ISNUMBER(FIND("SUM",W20)) -> TRUE | U20: =AND(ISNUMBER(FIND("=",W20)),ISNUMBER(FIND("(",W20)),ISNUMBER(FIND(":",W20))) -> TRUE | V20: 9 | W20: =_xlfn.FORMULATEXT('XL-Test'!N74) -> =SUM(N51:N73)
C22: Cek Manual | D22: =AND(ISNUMBER(FIND("=",W2)),ISNUMBER(FIND("(",W2)),ISNUMBER(FIND(":",W2)),D68) -> TRUE | E22: =AND(ISNUMBER(FIND("=",X2)),ISNUMBER(FIND("(",X2)),ISNUMBER(FIND(":",X2)),E68) -> TRUE | F22: =AND(ISNUMBER(FIND("=",Y2)),ISNUMBER(FIND("(",Y2)),ISNUMBER(FIND(":",Y2)),F68) -> TRUE | G22: =AND(ISNUMBER(FIND("=",Z2)),G68) -> TRUE | H22: =AND(ISNUMBER(FIND("=",AA2)),ISNUMBER(FIND("(",AA2)),ISNUMBER(FIND(":",AA2)),H68) -> TRUE | I22: =AND(ISNUMBER(FIND("=",AB2)),I68) -> TRUE | J22: =AND(ISNUMBER(FIND("=",AC2)),ISNUMBER(FIND("(",AC2)),J68) -> TRUE | K22: =AND(ISNUMBER(FIND("=",AD2)),ISNUMBER(FIND("(",AD2)),K68) -> TRUE | L22: =AND(ISNUMBER(FIND("=",AE2)),L68) -> TRUE | M22: =AND(U12,U13,U14,U15,U16,U17,U18,U19,U20) -> TRUE
C24: Cek Fungsi | D24: =IFERROR(LEN(W2)-LEN(SUBSTITUTE(W2,"(","")),99) -> 1 | E24: =IFERROR(LEN(X2)-LEN(SUBSTITUTE(X2,"(","")),99) -> 1 | F24: =IFERROR(LEN(Y2)-LEN(SUBSTITUTE(Y2,"(","")),99) -> 1 | G24: =IFERROR(LEN(Z2)-LEN(SUBSTITUTE(Z2,"(","")),99) -> 0 | H24: =IFERROR(LEN(AA2)-LEN(SUBSTITUTE(AA2,"(","")),99) -> 1 | I24: =IFERROR(LEN(AB2)-LEN(SUBSTITUTE(AB2,"(","")),99) -> 1 | J24: =IFERROR(LEN(AC2)-LEN(SUBSTITUTE(AC2,"(","")),99) -> 1 | K24: =IFERROR(LEN(AD2)-LEN(SUBSTITUTE(AD2,"(","")),99) -> 1 | L24: =IFERROR(LEN(AE2)-LEN(SUBSTITUTE(AE2,"(","")),99) -> 0 | M24: 1
D25: 1 | E25: 1 | F25: 1 | G25: 1 | H25: 1 | I25: 1 | J25: 1 | K25: 2 | L25: 1 | M25: 1
C26: Boolean | D26: =(D24<=D25) -> TRUE | E26: =(E24<=E25) -> TRUE | F26: =(F24<=F25) -> TRUE | G26: =(G24<=G25) -> TRUE | H26: =(H24<=H25) -> TRUE | I26: =(I24<=I25) -> TRUE | J26: =(J24<=J25) -> TRUE | K26: =(K24<=K25) -> TRUE | ... M26: =(M24<=M25) -> TRUE
C28: cek rumus | D28: =OR(ISNUMBER(FIND("VLO",W2)),ISNUMBER(FIND("XLO",W2))) -> TRUE | E28: =OR(ISNUMBER(FIND("VLO",X2)),ISNUMBER(FIND("XLO",X2))) -> TRUE | F28: =OR(ISNUMBER(FIND("VLO",Y2)),ISNUMBER(FIND("XLO",Y2))) -> TRUE | G28: =OR(ISNUMBER(FIND("SUM",Z2))) -> FALSE | H28: =OR(ISNUMBER(FIND("HLO",AA2)),ISNUMBER(FIND("XLO",AA2))) -> TRUE | I28: =OR(ISNUMBER(FIND("*",AB2))) -> TRUE | J28: =OR(ISNUMBER(FIND("VLO",AC2)),ISNUMBER(FIND("XLO",AC2))) -> TRUE | K28: =OR(AND(ISNUMBER(FIND("IND",AD2)),ISNUMBER(FIND("ATC",AD2))),ISNUMBER(FIND("XLO",AD2)),AND(ISNUMBER(FIND("XL",AD2)),ISNUMBER(FIND("CHOO",AD2))),AND(ISNUMBER(FIND("XLO",AD2)),ISNUMBER(FIND("IF",AD2)))) -> TRUE | L28: =OR(ISNUMBER(FIND("SUM",AE2)),ISNUMBER(FIND("-",AE2))) -> TRUE | M28: =AND(T12,T13,T14,T15,T16,T17,T18,T19,T20) -> TRUE
C30: Hasil | D30: =IF(AND(D28,D26),D19,D20) -> 33 | E30: =IF(AND(E28,E26),E19,E20) -> 1C | F30: =IF(AND(F28,F26),F19,F20) -> 1B | G30: =IF(AND(G28,G26),G19,G20) -> B9 | H30: =IF(AND(H28,H26),H19,H20) -> 1A | I30: =IF(AND(I28,I26),I19,I20) -> F2 | J30: =IF(AND(J28,J26),J19,J20) -> 40 | K30: =IF(AND(K28,K26),K19,K20) -> 1B | ... M30: =IF(AND(M28,M26),M19,M20) -> DA
C31: Gabung | D31: =D30&"-"&D16&";" -> 33-1BFDA; | E31: =E30&"-"&E16&";" -> 1C-CAEE; | F31: =F30&"-"&F16&";" -> 1B-1C7; | G31: =G30&"-"&G16&";" -> B9-28C8F; | H31: =H30&"-"&H16&";" -> 1A-4E2; | I31: =I30&"-"&I16&";" -> F2-272FD; | J31: =J30&"-"&J16&";" -> 40-30DCA; | K31: =K30&"-"&K16&";" -> 1B-1F756; | L31: =L30&"-"&L16&";" -> C6-1378C5; | M31: =M30&"-"&M16 -> DA-8A7A11
D33: =A2&"|"&D31&E31&F31&G31&H31&I31&J31&K31&L31&M31 -> EK6|33-1BFDA;1C-CAEE;1B-1C7;B9-28C8F;1A-4E2;F2-272FD;40-30DCA;1B-1F756;C6-1378C5;DA-8A7A11
C36: 1 | D36: =LEN(_xlfn.FORMULATEXT('XL-Test'!F51)) -> 31 | E36: =LEN(_xlfn.FORMULATEXT('XL-Test'!G51)) -> 31 | F36: =LEN(_xlfn.FORMULATEXT('XL-Test'!H51)) -> 31 | G36: =LEN(_xlfn.FORMULATEXT('XL-Test'!I51)) -> 42 | H36: =LEN(_xlfn.FORMULATEXT('XL-Test'!J51)) -> 33 | I36: =LEN(_xlfn.FORMULATEXT('XL-Test'!K51)) -> 14 | J36: =LEN(_xlfn.FORMULATEXT('XL-Test'!L51)) -> 35 | K36: =LEN(_xlfn.FORMULATEXT('XL-Test'!M51)) -> 51 | L36: =LEN(_xlfn.FORMULATEXT('XL-Test'!N51)) -> 12
C37: 2 | D37: =LEN(_xlfn.FORMULATEXT('XL-Test'!F52)) -> 31 | E37: =LEN(_xlfn.FORMULATEXT('XL-Test'!G52)) -> 31 | F37: =LEN(_xlfn.FORMULATEXT('XL-Test'!H52)) -> 31 | G37: =LEN(_xlfn.FORMULATEXT('XL-Test'!I52)) -> 42 | H37: =LEN(_xlfn.FORMULATEXT('XL-Test'!J52)) -> 33 | I37: =LEN(_xlfn.FORMULATEXT('XL-Test'!K52)) -> 14 | J37: =LEN(_xlfn.FORMULATEXT('XL-Test'!L52)) -> 35 | K37: =LEN(_xlfn.FORMULATEXT('XL-Test'!M52)) -> 51 | L37: =LEN(_xlfn.FORMULATEXT('XL-Test'!N52)) -> 12
C38: 3 | D38: =LEN(_xlfn.FORMULATEXT('XL-Test'!F53)) -> 31 | E38: =LEN(_xlfn.FORMULATEXT('XL-Test'!G53)) -> 31 | F38: =LEN(_xlfn.FORMULATEXT('XL-Test'!H53)) -> 31 | G38: =LEN(_xlfn.FORMULATEXT('XL-Test'!I53)) -> 42 | H38: =LEN(_xlfn.FORMULATEXT('XL-Test'!J53)) -> 33 | I38: =LEN(_xlfn.FORMULATEXT('XL-Test'!K53)) -> 14 | J38: =LEN(_xlfn.FORMULATEXT('XL-Test'!L53)) -> 35 | K38: =LEN(_xlfn.FORMULATEXT('XL-Test'!M53)) -> 51 | L38: =LEN(_xlfn.FORMULATEXT('XL-Test'!N53)) -> 12
C39: 4 | D39: =LEN(_xlfn.FORMULATEXT('XL-Test'!F54)) -> 31 | E39: =LEN(_xlfn.FORMULATEXT('XL-Test'!G54)) -> 31 | F39: =LEN(_xlfn.FORMULATEXT('XL-Test'!H54)) -> 31 | G39: =LEN(_xlfn.FORMULATEXT('XL-Test'!I54)) -> 42 | H39: =LEN(_xlfn.FORMULATEXT('XL-Test'!J54)) -> 33 | I39: =LEN(_xlfn.FORMULATEXT('XL-Test'!K54)) -> 14 | J39: =LEN(_xlfn.FORMULATEXT('XL-Test'!L54)) -> 35 | K39: =LEN(_xlfn.FORMULATEXT('XL-Test'!M54)) -> 51 | L39: =LEN(_xlfn.FORMULATEXT('XL-Test'!N54)) -> 12
C40: 5 | D40: =LEN(_xlfn.FORMULATEXT('XL-Test'!F55)) -> 31 | E40: =LEN(_xlfn.FORMULATEXT('XL-Test'!G55)) -> 31 | F40: =LEN(_xlfn.FORMULATEXT('XL-Test'!H55)) -> 31 | G40: =LEN(_xlfn.FORMULATEXT('XL-Test'!I55)) -> 42 | H40: =LEN(_xlfn.FORMULATEXT('XL-Test'!J55)) -> 33 | I40: =LEN(_xlfn.FORMULATEXT('XL-Test'!K55)) -> 14 | J40: =LEN(_xlfn.FORMULATEXT('XL-Test'!L55)) -> 35 | K40: =LEN(_xlfn.FORMULATEXT('XL-Test'!M55)) -> 51 | L40: =LEN(_xlfn.FORMULATEXT('XL-Test'!N55)) -> 12
C41: 6 | D41: =LEN(_xlfn.FORMULATEXT('XL-Test'!F56)) -> 31 | E41: =LEN(_xlfn.FORMULATEXT('XL-Test'!G56)) -> 31 | F41: =LEN(_xlfn.FORMULATEXT('XL-Test'!H56)) -> 31 | G41: =LEN(_xlfn.FORMULATEXT('XL-Test'!I56)) -> 42 | H41: =LEN(_xlfn.FORMULATEXT('XL-Test'!J56)) -> 33 | I41: =LEN(_xlfn.FORMULATEXT('XL-Test'!K56)) -> 14 | J41: =LEN(_xlfn.FORMULATEXT('XL-Test'!L56)) -> 35 | K41: =LEN(_xlfn.FORMULATEXT('XL-Test'!M56)) -> 51 | L41: =LEN(_xlfn.FORMULATEXT('XL-Test'!N56)) -> 12
C42: 7 | D42: =LEN(_xlfn.FORMULATEXT('XL-Test'!F57)) -> 31 | E42: =LEN(_xlfn.FORMULATEXT('XL-Test'!G57)) -> 31 | F42: =LEN(_xlfn.FORMULATEXT('XL-Test'!H57)) -> 31 | G42: =LEN(_xlfn.FORMULATEXT('XL-Test'!I57)) -> 42 | H42: =LEN(_xlfn.FORMULATEXT('XL-Test'!J57)) -> 33 | I42: =LEN(_xlfn.FORMULATEXT('XL-Test'!K57)) -> 14 | J42: =LEN(_xlfn.FORMULATEXT('XL-Test'!L57)) -> 35 | K42: =LEN(_xlfn.FORMULATEXT('XL-Test'!M57)) -> 51 | L42: =LEN(_xlfn.FORMULATEXT('XL-Test'!N57)) -> 12
C43: 8 | D43: =LEN(_xlfn.FORMULATEXT('XL-Test'!F58)) -> 31 | E43: =LEN(_xlfn.FORMULATEXT('XL-Test'!G58)) -> 31 | F43: =LEN(_xlfn.FORMULATEXT('XL-Test'!H58)) -> 31 | G43: =LEN(_xlfn.FORMULATEXT('XL-Test'!I58)) -> 42 | H43: =LEN(_xlfn.FORMULATEXT('XL-Test'!J58)) -> 33 | I43: =LEN(_xlfn.FORMULATEXT('XL-Test'!K58)) -> 14 | J43: =LEN(_xlfn.FORMULATEXT('XL-Test'!L58)) -> 35 | K43: =LEN(_xlfn.FORMULATEXT('XL-Test'!M58)) -> 51 | L43: =LEN(_xlfn.FORMULATEXT('XL-Test'!N58)) -> 12
C44: 9 | D44: =LEN(_xlfn.FORMULATEXT('XL-Test'!F59)) -> 31 | E44: =LEN(_xlfn.FORMULATEXT('XL-Test'!G59)) -> 31 | F44: =LEN(_xlfn.FORMULATEXT('XL-Test'!H59)) -> 31 | G44: =LEN(_xlfn.FORMULATEXT('XL-Test'!I59)) -> 42 | H44: =LEN(_xlfn.FORMULATEXT('XL-Test'!J59)) -> 33 | I44: =LEN(_xlfn.FORMULATEXT('XL-Test'!K59)) -> 14 | J44: =LEN(_xlfn.FORMULATEXT('XL-Test'!L59)) -> 35 | K44: =LEN(_xlfn.FORMULATEXT('XL-Test'!M59)) -> 51 | L44: =LEN(_xlfn.FORMULATEXT('XL-Test'!N59)) -> 12
C45: 10 | D45: =LEN(_xlfn.FORMULATEXT('XL-Test'!F60)) -> 31 | E45: =LEN(_xlfn.FORMULATEXT('XL-Test'!G60)) -> 31 | F45: =LEN(_xlfn.FORMULATEXT('XL-Test'!H60)) -> 31 | G45: =LEN(_xlfn.FORMULATEXT('XL-Test'!I60)) -> 42 | H45: =LEN(_xlfn.FORMULATEXT('XL-Test'!J60)) -> 33 | I45: =LEN(_xlfn.FORMULATEXT('XL-Test'!K60)) -> 14 | J45: =LEN(_xlfn.FORMULATEXT('XL-Test'!L60)) -> 35 | K45: =LEN(_xlfn.FORMULATEXT('XL-Test'!M60)) -> 51 | L45: =LEN(_xlfn.FORMULATEXT('XL-Test'!N60)) -> 12
C46: 11 | D46: =LEN(_xlfn.FORMULATEXT('XL-Test'!F61)) -> 31 | E46: =LEN(_xlfn.FORMULATEXT('XL-Test'!G61)) -> 31 | F46: =LEN(_xlfn.FORMULATEXT('XL-Test'!H61)) -> 31 | G46: =LEN(_xlfn.FORMULATEXT('XL-Test'!I61)) -> 42 | H46: =LEN(_xlfn.FORMULATEXT('XL-Test'!J61)) -> 33 | I46: =LEN(_xlfn.FORMULATEXT('XL-Test'!K61)) -> 14 | J46: =LEN(_xlfn.FORMULATEXT('XL-Test'!L61)) -> 35 | K46: =LEN(_xlfn.FORMULATEXT('XL-Test'!M61)) -> 51 | L46: =LEN(_xlfn.FORMULATEXT('XL-Test'!N61)) -> 12
C47: 12 | D47: =LEN(_xlfn.FORMULATEXT('XL-Test'!F62)) -> 31 | E47: =LEN(_xlfn.FORMULATEXT('XL-Test'!G62)) -> 31 | F47: =LEN(_xlfn.FORMULATEXT('XL-Test'!H62)) -> 31 | G47: =LEN(_xlfn.FORMULATEXT('XL-Test'!I62)) -> 42 | H47: =LEN(_xlfn.FORMULATEXT('XL-Test'!J62)) -> 33 | I47: =LEN(_xlfn.FORMULATEXT('XL-Test'!K62)) -> 14 | J47: =LEN(_xlfn.FORMULATEXT('XL-Test'!L62)) -> 35 | K47: =LEN(_xlfn.FORMULATEXT('XL-Test'!M62)) -> 51 | L47: =LEN(_xlfn.FORMULATEXT('XL-Test'!N62)) -> 12
...
