Workbook
Name DFGO: DF!$O$40
Name Kode_jawaban: DF!$C$42

Sheet XL-Test 
A19: Intruksi
B21: Kasus : | C21: Easy Level - Latihan Soal VLOOKUP dan HLOOKUP
B22: Soal :
B23: 1 | C23: Isi Nama Pelanggan (gunakan fungsi VLOOKUP / HLOOKUP) dari table pelanggan
B24: 2 | C24: Isi Nama Produk (gunakan fungsi VLOOKUP / HLOOKUP) dari table Kode Produk
B25: 3 | C25: Isi Harga Satuan (gunakan fungsi VLOOKUP / HLOOKUP) dari table kode produk
B26: 4 | C26: Isi Total Penjualan (gunakan rumus perkalian)
B27: 5 | C27: isi kolom Diskon dengan ketentuan :
C28: Jika QTY (kuantitas) pembelian di atas 200, maka diskon 10%, jika di atas 500, maka 20% (hitung menggunakan rumus IF)
B29: 6 | C29: Isi Penjualan Bersih (gunakan rumus perkalian)
B30: 7 | C30: Hitung total QTY dan Penjualan Bersih (tidak termasuk contoh)
B31: 8 | C31: Hitung rata-rata QTY dan Penjualan Bersih (tidak termasuk contoh)
B33: Sudah selesai mengerjakan? kirim Kode Soal dan Kode Jawaban diatas ke alamat : https://belajarexcel.id/xl-test/jawaban untuk mengecek hasilnya
B34: atau klik tombol disamping
B39: DAFTAR PENJUALAN
B40: TOKO BANGUNAN BERKAH
E43: 1 | G43: 2 | I43: 3 | J43: 4 | K43: 5 | L43: 6
A44: NO. | C44: TANGGAL | D44: KODE PELANGGAN | E44: NAMA PELANGGAN | F44: KODE PRODUK | G44: NAMA PRODUK | H44: QTY | I44: HARGA SATUAN | J44: TOTAL PENJUALAN | K44: DISKON | L44: PENJUALAN BERSIH
A45: Contoh | C45: 1-Nov | D45: BK-02 | E45: Toko Beni Kusuma | F45: B-10 | G45: Besi 10 Meter | H45: 350 | I45: 425000 | J45: 148750000 | K45: 0.1 | L45: 133875000 | N45: Kode Pelanggan
A47: 1 | C47: 1-Nov | D47: AB-01 | E47: =VLOOKUP(D47,$N$47:$O$50,2,) -> Toko Ahmad Budiman | F47: B-05 | G47: =HLOOKUP(F47,$N$53:$R$55,2,) -> Besi 5 Meter | H47: 240 | I47: =HLOOKUP(F47,$N$53:$R$55,3,) -> 250000 | J47: =I47*H47 -> 60000000 | K47: {=_xlfn.IFS(H47>500, 20%,H47>200, 10%, H47<200, 0)} -> 0.1 | L47: =J47-(J47*K47) -> 54000000 | N47: KODE | O47: NAMA PELANGGAN
A48: 2 | C48: 1-Nov | D48: BK-02 | E48: =VLOOKUP(D48,$N$47:$O$50,2,) -> Toko Beni Kusuma | F48: B-10 | G48: =HLOOKUP(F48,$N$53:$R$55,2,) -> Besi 10 Meter | H48: 350 | I48: =HLOOKUP(F48,$N$53:$R$55,3,) -> 425000 | J48: =I48*H48 -> 148750000 | K48: {=_xlfn.IFS(H48>500, 20%,H48>200, 10%, H48<200, 0)} -> 0.1 | L48: =J48-(J48*K48) -> 133875000 | N48: AB-01 | O48: Toko Ahmad Budiman
A49: 3 | C49: 1-Nov | D49: CJ-03 | E49: =VLOOKUP(D49,$N$47:$O$50,2,) -> Toko Chris John | F49: P-05 | G49: =HLOOKUP(F49,$N$53:$R$55,2,) -> Pipa 5 Meter | H49: 130 | I49: =HLOOKUP(F49,$N$53:$R$55,3,) -> 78000 | J49: =I49*H49 -> 10140000 | K49: {=_xlfn.IFS(H49>500, 20%,H49>200, 10%, H49<200, 0)} -> 0 | L49: =J49-(J49*K49) -> 10140000 | N49: BK-02 | O49: Toko Beni Kusuma
A50: 4 | C50: 2-Nov | D50: CJ-03 | E50: =VLOOKUP(D50,$N$47:$O$50,2,) -> Toko Chris John | F50: P-10 | G50: =HLOOKUP(F50,$N$53:$R$55,2,) -> Pipa 10 Meter | H50: 560 | I50: =HLOOKUP(F50,$N$53:$R$55,3,) -> 140000 | J50: =I50*H50 -> 78400000 | K50: {=_xlfn.IFS(H50>500, 20%,H50>200, 10%, H50<200, 0)} -> 0.2 | L50: =J50-(J50*K50) -> 62720000 | N50: CJ-03 | O50: Toko Chris John
A51: 5 | C51: 2-Nov | D51: BK-02 | E51: =VLOOKUP(D51,$N$47:$O$50,2,) -> Toko Beni Kusuma | F51: B-05 | G51: =HLOOKUP(F51,$N$53:$R$55,2,) -> Besi 5 Meter | H51: 780 | I51: =HLOOKUP(F51,$N$53:$R$55,3,) -> 250000 | J51: =I51*H51 -> 195000000 | K51: {=_xlfn.IFS(H51>500, 20%,H51>200, 10%, H51<200, 0)} -> 0.2 | L51: =J51-(J51*K51) -> 156000000
A52: 6 | C52: 2-Nov | D52: AB-01 | E52: =VLOOKUP(D52,$N$47:$O$50,2,) -> Toko Ahmad Budiman | F52: B-10 | G52: =HLOOKUP(F52,$N$53:$R$55,2,) -> Besi 10 Meter | H52: 890 | I52: =HLOOKUP(F52,$N$53:$R$55,3,) -> 425000 | J52: =I52*H52 -> 378250000 | K52: {=_xlfn.IFS(H52>500, 20%,H52>200, 10%, H52<200, 0)} -> 0.2 | L52: =J52-(J52*K52) -> 302600000 | N52: Kode Produk
A53: 7 | C53: 2-Nov | D53: BK-02 | E53: =VLOOKUP(D53,$N$47:$O$50,2,) -> Toko Beni Kusuma | F53: P-05 | G53: =HLOOKUP(F53,$N$53:$R$55,2,) -> Pipa 5 Meter | H53: 420 | I53: =HLOOKUP(F53,$N$53:$R$55,3,) -> 78000 | J53: =I53*H53 -> 32760000 | K53: {=_xlfn.IFS(H53>500, 20%,H53>200, 10%, H53<200, 0)} -> 0.1 | L53: =J53-(J53*K53) -> 29484000 | N53: KODE | O53: B-05 | P53: B-10 | Q53: P-05 | R53: P-10
A54: 8 | C54: 2-Nov | D54: AB-01 | E54: =VLOOKUP(D54,$N$47:$O$50,2,) -> Toko Ahmad Budiman | F54: P-10 | G54: =HLOOKUP(F54,$N$53:$R$55,2,) -> Pipa 10 Meter | H54: 110 | I54: =HLOOKUP(F54,$N$53:$R$55,3,) -> 140000 | J54: =I54*H54 -> 15400000 | K54: {=_xlfn.IFS(H54>500, 20%,H54>200, 10%, H54<200, 0)} -> 0 | L54: =J54-(J54*K54) -> 15400000 | N54: NAMA | O54: Besi 5 Meter | P54: Besi 10 Meter | Q54: Pipa 5 Meter | R54: Pipa 10 Meter
A55: 9 | C55: 2-Nov | D55: CJ-03 | E55: =VLOOKUP(D55,$N$47:$O$50,2,) -> Toko Chris John | F55: B-05 | G55: =HLOOKUP(F55,$N$53:$R$55,2,) -> Besi 5 Meter | H55: 720 | I55: =HLOOKUP(F55,$N$53:$R$55,3,) -> 250000 | J55: =I55*H55 -> 180000000 | K55: {=_xlfn.IFS(H55>500, 20%,H55>200, 10%, H55<200, 0)} -> 0.2 | L55: =J55-(J55*K55) -> 144000000 | N55: HARGA SATUAN | O55: 250000 | P55: 425000 | Q55: 78000 | R55: 140000
A56: 10 | C56: 2-Nov | D56: BK-02 | E56: =VLOOKUP(D56,$N$47:$O$50,2,) -> Toko Beni Kusuma | F56: B-10 | G56: =HLOOKUP(F56,$N$53:$R$55,2,) -> Besi 10 Meter | H56: 120 | I56: =HLOOKUP(F56,$N$53:$R$55,3,) -> 425000 | J56: =I56*H56 -> 51000000 | K56: {=_xlfn.IFS(H56>500, 20%,H56>200, 10%, H56<200, 0)} -> 0 | L56: =J56-(J56*K56) -> 51000000
A57: 11 | C57: 2-Nov | D57: AB-01 | E57: =VLOOKUP(D57,$N$47:$O$50,2,) -> Toko Ahmad Budiman | F57: P-05 | G57: =HLOOKUP(F57,$N$53:$R$55,2,) -> Pipa 5 Meter | H57: 120 | I57: =HLOOKUP(F57,$N$53:$R$55,3,) -> 78000 | J57: =I57*H57 -> 9360000 | K57: {=_xlfn.IFS(H57>500, 20%,H57>200, 10%, H57<200, 0)} -> 0 | L57: =J57-(J57*K57) -> 9360000
A58: 12 | C58: 2-Nov | D58: AB-01 | E58: =VLOOKUP(D58,$N$47:$O$50,2,) -> Toko Ahmad Budiman | F58: P-10 | G58: =HLOOKUP(F58,$N$53:$R$55,2,) -> Pipa 10 Meter | H58: 550 | I58: =HLOOKUP(F58,$N$53:$R$55,3,) -> 140000 | J58: =I58*H58 -> 77000000 | K58: {=_xlfn.IFS(H58>500, 20%,H58>200, 10%, H58<200, 0)} -> 0.2 | L58: =J58-(J58*K58) -> 61600000
A59: 13 | C59: 2-Nov | D59: BK-02 | E59: =VLOOKUP(D59,$N$47:$O$50,2,) -> Toko Beni Kusuma | F59: P-05 | G59: =HLOOKUP(F59,$N$53:$R$55,2,) -> Pipa 5 Meter | H59: 580 | I59: =HLOOKUP(F59,$N$53:$R$55,3,) -> 78000 | J59: =I59*H59 -> 45240000 | K59: {=_xlfn.IFS(H59>500, 20%,H59>200, 10%, H59<200, 0)} -> 0.2 | L59: =J59-(J59*K59) -> 36192000
A60: 14 | C60: 3-Nov | D60: AB-01 | E60: =VLOOKUP(D60,$N$47:$O$50,2,) -> Toko Ahmad Budiman | F60: P-10 | G60: =HLOOKUP(F60,$N$53:$R$55,2,) -> Pipa 10 Meter | H60: 620 | I60: =HLOOKUP(F60,$N$53:$R$55,3,) -> 140000 | J60: =I60*H60 -> 86800000 | K60: {=_xlfn.IFS(H60>500, 20%,H60>200, 10%, H60<200, 0)} -> 0.2 | L60: =J60-(J60*K60) -> 69440000
A61: 15 | C61: 3-Nov | D61: CJ-03 | E61: =VLOOKUP(D61,$N$47:$O$50,2,) -> Toko Chris John | F61: P-10 | G61: =HLOOKUP(F61,$N$53:$R$55,2,) -> Pipa 10 Meter | H61: 900 | I61: =HLOOKUP(F61,$N$53:$R$55,3,) -> 140000 | J61: =I61*H61 -> 126000000 | K61: {=_xlfn.IFS(H61>500, 20%,H61>200, 10%, H61<200, 0)} -> 0.2 | L61: =J61-(J61*K61) -> 100800000
A62: Total QTY | H62: =SUM(H47:H61) -> 7090 | I62: Total Penjualan Bersih | L62: =SUM(L47:L61) -> 1236611000 | M62: 7
A63: Rata-rata QTY | H63: =AVERAGE(H47:H61) -> 472.66667 | I63: Rata-rata Penjualan Bersih | L63: =AVERAGE(L47:L61) -> 82440733 | M63: 8

Sheet About
I6: XL-TEST adalah platform inovatif yang menyediakan latihan Excel interaktif dengan pemeriksaan otomatis,
I7: sehingga pengguna dapat langsung mengetahui jawaban yang benar maupun salah.
I10: Terdapat 5 Level soal :
J12: Easy Level | L12: (⭐)
J13: Medium Level | L13: (⭐⭐)
J14: Hard Level | L14: (⭐⭐⭐)
J15: Extreme Level | L15: (⭐⭐⭐⭐)
J16: Championship Level | L16: (⭐⭐⭐⭐⭐)
B17: Saya adalah seorang Excel Holic yang percaya bahwa setiap angka memiliki cerita yang bisa ditemukan dengan cara yang tepat. | I17: Free Access
B18: “Excel bukan cuma soal kerjaan tapi juga hobi yang aku nikmati.” | I18: https://belajarexcel.id/xl-test/
B19: Contact :
B20: 🌐 Web | C20: https://setiadi.me
B21: 🪡threads | C21: https://www.threads.com/@andisetiadi
D27: Perlu Video Penjelasan atau Kunci Jawaban ?
D28: Scan barcode atau kunjungi
D29: https://lynk.id/setiadi/page/jawaban-xl-test

Sheet DF
A1: DEF | C1: 1 | D1: 2 | E1: 3 | F1: 4 | G1: 5 | H1: 6 | I1: 7 | J1: 8 | L1: 1a | M1: 2a | P1: 1 | Q1: 2 | R1: 3 | S1: 4 | T1: 5 | U1: 6
A2: EC4 | B2: 1 | C2: =UPPER('XL-Test '!E47) -> TOKO AHMAD BUDIMAN | D2: =UPPER('XL-Test '!G47) -> BESI 5 METER | E2: ='XL-Test '!I47 -> 250000 | F2: ='XL-Test '!J47 -> 60000000 | G2: ='XL-Test '!K47 -> 0.1 | H2: ='XL-Test '!L47 -> 54000000 | I2: ='XL-Test '!H62 -> 7090 | J2: ='XL-Test '!H63 -> 472.66667 | L2: =CODE(MID(C2,6,1))+CODE(MID(C2,7,1))+CODE(RIGHT(C2,1)) -> 215 | M2: =CODE(MID(D2,5,1))+CODE(MID(D2,2,1))+CODE(RIGHT(D2,1))+CODE(LEFT(D2,1))+CODE(MID(D2,6,1)) -> 302 | O2: 1 | P2: =_xlfn.FORMULATEXT('XL-Test '!E47) -> =VLOOKUP(D47,$N$47:$O$50,2,) | Q2: =_xlfn.FORMULATEXT('XL-Test '!G47) -> =HLOOKUP(F47,$N$53:$R$55,2,) | R2: =_xlfn.FORMULATEXT('XL-Test '!I47) -> =HLOOKUP(F47,$N$53:$R$55,3,) | S2: =_xlfn.FORMULATEXT('XL-Test '!J47) -> =I47*H47 | T2: =_xlfn.FORMULATEXT('XL-Test '!K47) -> =IFS(H47>500, 20%,H47>200, 10%, H47<200, 0) | U2: =_xlfn.FORMULATEXT('XL-Test '!L47) -> =J47-(J47*K47)
B3: 2 | C3: =UPPER('XL-Test '!E48) -> TOKO BENI KUSUMA | D3: =UPPER('XL-Test '!G48) -> BESI 10 METER | E3: ='XL-Test '!I48 -> 425000 | F3: ='XL-Test '!J48 -> 148750000 | G3: ='XL-Test '!K48 -> 0.1 | H3: ='XL-Test '!L48 -> 133875000 | I3: ='XL-Test '!L62 -> 1236611000 | J3: ='XL-Test '!L63 -> 82440733 | L3: =CODE(MID(C3,6,1))+CODE(MID(C3,7,1))+CODE(RIGHT(C3,1)) -> 200 | M3: =CODE(MID(D3,5,1))+CODE(MID(D3,2,1))+CODE(RIGHT(D3,1))+CODE(LEFT(D3,1))+CODE(MID(D3,6,1)) -> 298 | O3: 2 | P3: =_xlfn.FORMULATEXT('XL-Test '!G47) -> =HLOOKUP(F47,$N$53:$R$55,2,)
B4: 3 | C4: =UPPER('XL-Test '!E49) -> TOKO CHRIS JOHN | D4: =UPPER('XL-Test '!G49) -> PIPA 5 METER | E4: ='XL-Test '!I49 -> 78000 | F4: ='XL-Test '!J49 -> 10140000 | G4: ='XL-Test '!K49 -> 0 | H4: ='XL-Test '!L49 -> 10140000 | L4: =CODE(MID(C4,6,1))+CODE(MID(C4,7,1))+CODE(RIGHT(C4,1)) -> 217 | M4: =CODE(MID(D4,5,1))+CODE(MID(D4,2,1))+CODE(RIGHT(D4,1))+CODE(LEFT(D4,1))+CODE(MID(D4,6,1)) -> 320 | O4: 3 | P4: =_xlfn.FORMULATEXT('XL-Test '!I47) -> =HLOOKUP(F47,$N$53:$R$55,3,)
B5: 4 | C5: =UPPER('XL-Test '!E50) -> TOKO CHRIS JOHN | D5: =UPPER('XL-Test '!G50) -> PIPA 10 METER | E5: ='XL-Test '!I50 -> 140000 | F5: ='XL-Test '!J50 -> 78400000 | G5: ='XL-Test '!K50 -> 0.2 | H5: ='XL-Test '!L50 -> 62720000 | L5: =CODE(MID(C5,6,1))+CODE(MID(C5,7,1))+CODE(RIGHT(C5,1)) -> 217 | M5: =CODE(MID(D5,5,1))+CODE(MID(D5,2,1))+CODE(RIGHT(D5,1))+CODE(LEFT(D5,1))+CODE(MID(D5,6,1)) -> 316 | O5: 4 | P5: =_xlfn.FORMULATEXT('XL-Test '!J47) -> =I47*H47
B6: 5 | C6: =UPPER('XL-Test '!E51) -> TOKO BENI KUSUMA | D6: =UPPER('XL-Test '!G51) -> BESI 5 METER | E6: ='XL-Test '!I51 -> 250000 | F6: ='XL-Test '!J51 -> 195000000 | G6: ='XL-Test '!K51 -> 0.2 | H6: ='XL-Test '!L51 -> 156000000 | L6: =CODE(MID(C6,6,1))+CODE(MID(C6,7,1))+CODE(RIGHT(C6,1)) -> 200 | M6: =CODE(MID(D6,5,1))+CODE(MID(D6,2,1))+CODE(RIGHT(D6,1))+CODE(LEFT(D6,1))+CODE(MID(D6,6,1)) -> 302 | O6: 5 | P6: =_xlfn.FORMULATEXT('XL-Test '!K47) -> =IFS(H47>500, 20%,H47>200, 10%, H47<200, 0)
B7: 6 | C7: =UPPER('XL-Test '!E52) -> TOKO AHMAD BUDIMAN | D7: =UPPER('XL-Test '!G52) -> BESI 10 METER | E7: ='XL-Test '!I52 -> 425000 | F7: ='XL-Test '!J52 -> 378250000 | G7: ='XL-Test '!K52 -> 0.2 | H7: ='XL-Test '!L52 -> 302600000 | I7: =I3-I2 -> 1236603910 | J7: =J3-J2 -> 82440261 | L7: =CODE(MID(C7,6,1))+CODE(MID(C7,7,1))+CODE(RIGHT(C7,1)) -> 215 | M7: =CODE(MID(D7,5,1))+CODE(MID(D7,2,1))+CODE(RIGHT(D7,1))+CODE(LEFT(D7,1))+CODE(MID(D7,6,1)) -> 298 | O7: 6 | P7: =_xlfn.FORMULATEXT('XL-Test '!L47) -> =J47-(J47*K47)
B8: 7 | C8: =UPPER('XL-Test '!E53) -> TOKO BENI KUSUMA | D8: =UPPER('XL-Test '!G53) -> PIPA 5 METER | E8: ='XL-Test '!I53 -> 78000 | F8: ='XL-Test '!J53 -> 32760000 | G8: ='XL-Test '!K53 -> 0.1 | H8: ='XL-Test '!L53 -> 29484000 | I8: =INT(SUM(I2:I7)/10000) -> 247322 | J8: =INT(SUM(J2:J7)/10000) -> 16488 | L8: =CODE(MID(C8,6,1))+CODE(MID(C8,7,1))+CODE(RIGHT(C8,1)) -> 200 | M8: =CODE(MID(D8,5,1))+CODE(MID(D8,2,1))+CODE(RIGHT(D8,1))+CODE(LEFT(D8,1))+CODE(MID(D8,6,1)) -> 320 | Q8: Formula
B9: 8 | C9: =UPPER('XL-Test '!E54) -> TOKO AHMAD BUDIMAN | D9: =UPPER('XL-Test '!G54) -> PIPA 10 METER | E9: ='XL-Test '!I54 -> 140000 | F9: ='XL-Test '!J54 -> 15400000 | G9: ='XL-Test '!K54 -> 0 | H9: ='XL-Test '!L54 -> 15400000 | L9: =CODE(MID(C9,6,1))+CODE(MID(C9,7,1))+CODE(RIGHT(C9,1)) -> 215 | M9: =CODE(MID(D9,5,1))+CODE(MID(D9,2,1))+CODE(RIGHT(D9,1))+CODE(LEFT(D9,1))+CODE(MID(D9,6,1)) -> 316 | O9: 7a | P9: =_xlfn.FORMULATEXT('XL-Test '!H62) -> =SUM(H47:H61) | Q9: =AND(ISNUMBER(FIND("=",P9)),ISNUMBER(FIND("(",P9))) -> TRUE | R9: =ISNUMBER(FIND("SUM",P9)) -> TRUE
B10: 9 | C10: =UPPER('XL-Test '!E55) -> TOKO CHRIS JOHN | D10: =UPPER('XL-Test '!G55) -> BESI 5 METER | E10: ='XL-Test '!I55 -> 250000 | F10: ='XL-Test '!J55 -> 180000000 | G10: ='XL-Test '!K55 -> 0.2 | H10: ='XL-Test '!L55 -> 144000000 | L10: =CODE(MID(C10,6,1))+CODE(MID(C10,7,1))+CODE(RIGHT(C10,1)) -> 217 | M10: =CODE(MID(D10,5,1))+CODE(MID(D10,2,1))+CODE(RIGHT(D10,1))+CODE(LEFT(D10,1))+CODE(MID(D10,6,1)) -> 302 | O10: 7b | P10: =_xlfn.FORMULATEXT('XL-Test '!L62) -> =SUM(L47:L61) | Q10: =AND(ISNUMBER(FIND("=",P10)),ISNUMBER(FIND("(",P10))) -> TRUE | R10: =ISNUMBER(FIND("SUM",P10)) -> TRUE
B11: 10 | C11: =UPPER('XL-Test '!E56) -> TOKO BENI KUSUMA | D11: =UPPER('XL-Test '!G56) -> BESI 10 METER | E11: ='XL-Test '!I56 -> 425000 | F11: ='XL-Test '!J56 -> 51000000 | G11: ='XL-Test '!K56 -> 0 | H11: ='XL-Test '!L56 -> 51000000 | L11: =CODE(MID(C11,6,1))+CODE(MID(C11,7,1))+CODE(RIGHT(C11,1)) -> 200 | M11: =CODE(MID(D11,5,1))+CODE(MID(D11,2,1))+CODE(RIGHT(D11,1))+CODE(LEFT(D11,1))+CODE(MID(D11,6,1)) -> 298 | O11: 8a | P11: =_xlfn.FORMULATEXT('XL-Test '!H63) -> =AVERAGE(H47:H61) | Q11: =AND(ISNUMBER(FIND("=",P11)),ISNUMBER(FIND("(",P11))) -> TRUE | R11: =ISNUMBER(FIND("AVE",P11)) -> TRUE
B12: 11 | C12: =UPPER('XL-Test '!E57) -> TOKO AHMAD BUDIMAN | D12: =UPPER('XL-Test '!G57) -> PIPA 5 METER | E12: ='XL-Test '!I57 -> 78000 | F12: ='XL-Test '!J57 -> 9360000 | G12: ='XL-Test '!K57 -> 0 | H12: ='XL-Test '!L57 -> 9360000 | L12: =CODE(MID(C12,6,1))+CODE(MID(C12,7,1))+CODE(RIGHT(C12,1)) -> 215 | M12: =CODE(MID(D12,5,1))+CODE(MID(D12,2,1))+CODE(RIGHT(D12,1))+CODE(LEFT(D12,1))+CODE(MID(D12,6,1)) -> 320 | O12: 8b | P12: =_xlfn.FORMULATEXT('XL-Test '!L63) -> =AVERAGE(L47:L61) | Q12: =AND(ISNUMBER(FIND("=",P12)),ISNUMBER(FIND("(",P12))) -> TRUE | R12: =ISNUMBER(FIND("AVE",P12)) -> TRUE
B13: 12 | C13: =UPPER('XL-Test '!E58) -> TOKO AHMAD BUDIMAN | D13: =UPPER('XL-Test '!G58) -> PIPA 10 METER | E13: ='XL-Test '!I58 -> 140000 | F13: ='XL-Test '!J58 -> 77000000 | G13: ='XL-Test '!K58 -> 0.2 | H13: ='XL-Test '!L58 -> 61600000 | L13: =CODE(MID(C13,6,1))+CODE(MID(C13,7,1))+CODE(RIGHT(C13,1)) -> 215 | M13: =CODE(MID(D13,5,1))+CODE(MID(D13,2,1))+CODE(RIGHT(D13,1))+CODE(LEFT(D13,1))+CODE(MID(D13,6,1)) -> 316
B14: 13 | C14: =UPPER('XL-Test '!E59) -> TOKO BENI KUSUMA | D14: =UPPER('XL-Test '!G59) -> PIPA 5 METER | E14: ='XL-Test '!I59 -> 78000 | F14: ='XL-Test '!J59 -> 45240000 | G14: ='XL-Test '!K59 -> 0.2 | H14: ='XL-Test '!L59 -> 36192000 | L14: =CODE(MID(C14,6,1))+CODE(MID(C14,7,1))+CODE(RIGHT(C14,1)) -> 200 | M14: =CODE(MID(D14,5,1))+CODE(MID(D14,2,1))+CODE(RIGHT(D14,1))+CODE(LEFT(D14,1))+CODE(MID(D14,6,1)) -> 320
B15: 14 | C15: =UPPER('XL-Test '!E60) -> TOKO AHMAD BUDIMAN | D15: =UPPER('XL-Test '!G60) -> PIPA 10 METER | E15: ='XL-Test '!I60 -> 140000 | F15: ='XL-Test '!J60 -> 86800000 | G15: ='XL-Test '!K60 -> 0.2 | H15: ='XL-Test '!L60 -> 69440000 | L15: =CODE(MID(C15,6,1))+CODE(MID(C15,7,1))+CODE(RIGHT(C15,1)) -> 215 | M15: =CODE(MID(D15,5,1))+CODE(MID(D15,2,1))+CODE(RIGHT(D15,1))+CODE(LEFT(D15,1))+CODE(MID(D15,6,1)) -> 316
B16: 15 | C16: =UPPER('XL-Test '!E61) -> TOKO CHRIS JOHN | D16: =UPPER('XL-Test '!G61) -> PIPA 10 METER | E16: ='XL-Test '!I61 -> 140000 | F16: ='XL-Test '!J61 -> 126000000 | G16: ='XL-Test '!K61 -> 0.2 | H16: ='XL-Test '!L61 -> 100800000 | L16: =CODE(MID(C16,6,1))+CODE(MID(C16,7,1))+CODE(RIGHT(C16,1)) -> 217 | M16: =CODE(MID(D16,5,1))+CODE(MID(D16,2,1))+CODE(RIGHT(D16,1))+CODE(LEFT(D16,1))+CODE(MID(D16,6,1)) -> 316
C18: =L18 -> 4620 | D18: =M18 -> 6834 | E18: =INT((SUM(E2:E16)+E3+E5+E8+E11+E12+E15)/1000) -> 4323 | F18: =INT((SUM(F2:F16)+F3+F5+F8+F11+F12+F15)/1000) -> 1901170 | G18: =INT((SUM(G2:G16)+G2+G3+G6+G9+G12+G14+G16)*1000) -> 2700 | H18: =INT((SUM(H2:H16)+H3+H5+H8+H11+H12+H15)/1000) -> 1592490 | I18: =I8 -> 247322 | J18: =J8 -> 16488 | L18: =INT((SUM(L2:L16)+L2+L3+L6+L9+L12+L14+L16)*1) -> 4620 | M18: =INT((SUM(M2:M16)+M2+M3+M6+M9+M12+M14+M16)*1) -> 6834
B20: Random1 | C20: 5114 | D20: 4710 | E20: 5112 | F20: 1191 | G20: 3621 | H20: 8934 | I20: 4271 | J20: 4045
B21: Random2 | C21: 14A45 | D21: F36C | E21: CB4D | F21: DE3A | G21: 15D09 | H21: 10248 | I21: F97B | J21: 10045
C22: 8 | D22: 19 | E22: 16 | F22: 4 | G22: 12 | H22: 19 | I22: 12 | J22: 1
B23: TRUE | C23: =LEFT(DEC2HEX(LEFT(C20,3)+C22),2) -> 20 | D23: =LEFT(DEC2HEX(LEFT(D20,3)+D22),2) -> 1E | E23: =LEFT(DEC2HEX(LEFT(E20,3)+E22),2) -> 20 | F23: =LEFT(DEC2HEX(LEFT(F20,3)+F22),2) -> 7B | G23: =LEFT(DEC2HEX(LEFT(G20,3)+G22),2) -> 17 | H23: =LEFT(DEC2HEX(LEFT(H20,3)+H22),2) -> 39 | I23: =LEFT(DEC2HEX(LEFT(I20,3)+I22),2) -> 1B | J23: =LEFT(DEC2HEX(LEFT(J20,3)+J22),2) -> 19
B24: FALSE | C24: =LEFT(DEC2HEX(RIGHT(C20,3)+C22),2) -> 7A | D24: =LEFT(DEC2HEX(RIGHT(D20,3)+D22),2) -> 2D | E24: =LEFT(DEC2HEX(RIGHT(E20,3)+E22),2) -> 80 | F24: =LEFT(DEC2HEX(RIGHT(F20,3)+F22),2) -> C3 | G24: =LEFT(DEC2HEX(RIGHT(G20,3)+G22),2) -> 27 | H24: =LEFT(DEC2HEX(RIGHT(H20,3)+H22),2) -> 3B | I24: =LEFT(DEC2HEX(RIGHT(I20,3)+I22),2) -> 11 | J24: =LEFT(DEC2HEX(RIGHT(J20,3)+J22),2) -> 2E
B25: Kosong | C25: =NOT(OR(C2="",C2=0)) -> TRUE | D25: =NOT(OR(D2="",D2=0)) -> TRUE | E25: =NOT(OR(E2="",E2=0)) -> TRUE | F25: =NOT(OR(F2="",F2=0)) -> TRUE | G25: =NOT(OR(G2="",G2=0)) -> TRUE | H25: =NOT(OR(H2="",H2=0)) -> TRUE | I25: =NOT(OR(I2="",I2=0)) -> TRUE | J25: =NOT(OR(J2="",J2=0)) -> TRUE
B26: Formula | C26: =AND(ISNUMBER(FIND("=",P2)),ISNUMBER(FIND("(",P2))) -> TRUE | D26: =AND(ISNUMBER(FIND("=",Q2)),ISNUMBER(FIND("(",Q2))) -> TRUE | E26: =AND(ISNUMBER(FIND("=",R2)),ISNUMBER(FIND("(",R2))) -> TRUE | F26: =AND(ISNUMBER(FIND("=",S2)),OR(ISNUMBER(FIND("(",S2)),ISNUMBER(FIND("*",S2)))) -> TRUE | G26: =AND(ISNUMBER(FIND("=",T2)),OR(ISNUMBER(FIND("(",T2)),ISNUMBER(FIND("*",T2)))) -> TRUE | H26: =AND(ISNUMBER(FIND("=",U2)),OR(ISNUMBER(FIND("(",U2)),ISNUMBER(FIND("*",U2)))) -> TRUE | I26: =AND(Q9:Q10) -> TRUE | J26: =AND(Q11:Q12) -> TRUE
B27: Drag | C27: =C66 -> TRUE | D27: =D66 -> TRUE | E27: =E66 -> TRUE | F27: =F66 -> TRUE | G27: =G66 -> TRUE | H27: =H66 -> TRUE | I27: TRUE | J27: TRUE
B28: Cek Type Data | C28: =ISTEXT(C2) -> TRUE | D28: =ISTEXT(D2) -> TRUE | E28: =ISNUMBER(E2) -> TRUE | F28: =ISNUMBER(F2) -> TRUE | G28: =ISNUMBER(G2) -> TRUE | H28: =ISNUMBER(H2) -> TRUE | I28: =AND(ISNUMBER(I2),ISNUMBER(I3)) -> TRUE | J28: =AND(ISNUMBER(J2),ISNUMBER(J3)) -> TRUE
A30: ** | B30: Fvalue | C30: =IFERROR(DEC2HEX(IF(AND(C25:C28),C18,C20)),"EEE") -> 120C | D30: =IFERROR(DEC2HEX(IF(AND(D25:D28),D18,D20)),"EEE") -> 1AB2 | E30: =IFERROR(DEC2HEX(IF(AND(E25:E28),E18,E20)),"EEE") -> 10E3 | F30: =IFERROR(DEC2HEX(IF(AND(F25:F28),F18,F20)),"EEE") -> 1D0272 | G30: =IFERROR(DEC2HEX(IF(AND(G25:G28),G18,G20)),"EEE") -> A8C | H30: =IFERROR(DEC2HEX(IF(AND(H25:H28),H18,H20)),"EEE") -> 184CAA | I30: =IFERROR(DEC2HEX(IF(AND(I25:I28),I18,I20)),"EEE") -> 3C61A | J30: =IFERROR(DEC2HEX(IF(AND(J25:J28),J18,J20)),"EEE") -> 4068
B32: Cek Formula | C32: =OR(ISNUMBER(FIND("VLO",P2)),ISNUMBER(FIND("XLO",P2))) -> TRUE | D32: =OR(ISNUMBER(FIND("HLO",Q2)),ISNUMBER(FIND("XLO",Q2))) -> TRUE | E32: =OR(ISNUMBER(FIND("HLO",R2)),ISNUMBER(FIND("XLO",R2))) -> TRUE | F32: =OR(ISNUMBER(FIND("*",S2)),ISNUMBER(FIND("PROD",S2))) -> TRUE | G32: =ISNUMBER(FIND("IF",P6)) -> TRUE | H32: =ISNUMBER(FIND("*",U2)) -> TRUE | I32: =AND(R9:R10) -> TRUE | J32: =AND(R11:R12) -> TRUE
B33: Cek Kurung | C33: =IFERROR(LEN(P2)-LEN(SUBSTITUTE(P2,"(","")),99) -> 1 | D33: =IFERROR(LEN(Q2)-LEN(SUBSTITUTE(Q2,"(","")),99) -> 1 | E33: =IFERROR(LEN(R2)-LEN(SUBSTITUTE(R2,"(","")),99) -> 1 | F33: =IFERROR(LEN(S2)-LEN(SUBSTITUTE(S2,"(","")),99) -> 0 | G33: =IFERROR(LEN(T2)-LEN(SUBSTITUTE(T2,"(","")),99) -> 1 | H33: =IFERROR(LEN(U2)-LEN(SUBSTITUTE(U2,"(","")),99) -> 1 | I33: =IFERROR(LEN(V2)-LEN(SUBSTITUTE(V2,"(","")),99) -> 0 | J33: =IFERROR(LEN(W2)-LEN(SUBSTITUTE(W2,"(","")),99) -> 0
C34: 1 | D34: 1 | E34: 1 | F34: 1 | G34: 2 | H34: 1 | I34: 1 | J34: 1
C35: =C33<=C34 -> TRUE | D35: =D33<=D34 -> TRUE | E35: =E33<=E34 -> TRUE | F35: =F33<=F34 -> TRUE | G35: =G33<=G34 -> TRUE | H35: =H33<=H34 -> TRUE | I35: =I33<=I34 -> TRUE | J35: =J33<=J34 -> TRUE
B37: ** | C37: =IF(AND(C35,C32),C23,C24) -> 20 | D37: =IF(AND(D35,D32),D23,D24) -> 1E | E37: =IF(AND(E35,E32),E23,E24) -> 20 | F37: =IF(AND(F35,F32),F23,F24) -> 7B | G37: =IF(AND(G35,G32),G23,G24) -> 17 | H37: =IF(AND(H35,H32),H23,H24) -> 39 | I37: =IF(AND(I35,I32),I23,I24) -> 1B | J37: =IF(AND(J35,J32),J23,J24) -> 19
B40: Final | C40: =C37&"-"&C30&";" -> 20-120C; | D40: =D37&"-"&D30&";" -> 1E-1AB2; | E40: =E37&"-"&E30&";" -> 20-10E3; | F40: =F37&"-"&F30&";" -> 7B-1D0272; | G40: =G37&"-"&G30&";" -> 17-A8C; | H40: =H37&"-"&H30&";" -> 39-184CAA; | I40: =I37&"-"&I30&";" -> 1B-3C61A; | J40: =J37&"-"&J30 -> 19-4068 | O40: =A2&"|"&C40&D40&E40&F40&G40&H40&I40&J40 -> EC4|20-120C;1E-1AB2;20-10E3;7B-1D0272;17-A8C;39-184CAA;1B-3C61A;19-4068
C42: =N48 -> EC4|20-120C;1E-1AB2;20-10E3;7B-1D0272;17-A8C;39-184CAA;1B-3C61A;19-4068 | N42: LO | O42: IK
N43: PO | O43: DF
N44: SK | O44: GO
N45: SK | O45: BH
A46: Drag | B46: 1 | C46: =IFERROR(LEN(_xlfn.FORMULATEXT('XL-Test '!E47)),0) -> 28 | D46: =IFERROR(LEN(_xlfn.FORMULATEXT('XL-Test '!G47)),0) -> 28 | E46: =IFERROR(LEN(_xlfn.FORMULATEXT('XL-Test '!I47)),0) -> 28 | F46: =IFERROR(LEN(_xlfn.FORMULATEXT('XL-Test '!J47)),0) -> 8 | G46: =IFERROR(LEN(_xlfn.FORMULATEXT('XL-Test '!K47)),0) -> 43 | H46: =IFERROR(LEN(_xlfn.FORMULATEXT('XL-Test '!L47)),0) -> 14
B47: 2 | C47: =IFERROR(LEN(_xlfn.FORMULATEXT('XL-Test '!E48)),0) -> 28 | D47: =IFERROR(LEN(_xlfn.FORMULATEXT('XL-Test '!G48)),0) -> 28 | E47: =IFERROR(LEN(_xlfn.FORMULATEXT('XL-Test '!I48)),0) -> 28 | F47: =IFERROR(LEN(_xlfn.FORMULATEXT('XL-Test '!J48)),0) -> 8 | G47: =IFERROR(LEN(_xlfn.FORMULATEXT('XL-Test '!K48)),0) -> 43 | H47: =IFERROR(LEN(_xlfn.FORMULATEXT('XL-Test '!L48)),0) -> 14 | N47: =VLOOKUP("PO",N42:O45,2,0)&VLOOKUP("SK",N42:O45,2,0) -> DFGO
B48: 3 | C48: =IFERROR(LEN(_xlfn.FORMULATEXT('XL-Test '!E49)),0) -> 28 | D48: =IFERROR(LEN(_xlfn.FORMULATEXT('XL-Test '!G49)),0) -> 28 | E48: =IFERROR(LEN(_xlfn.FORMULATEXT('XL-Test '!I49)),0) -> 28 | F48: =IFERROR(LEN(_xlfn.FORMULATEXT('XL-Test '!J49)),0) -> 8 | G48: =IFERROR(LEN(_xlfn.FORMULATEXT('XL-Test '!K49)),0) -> 43 | H48: =IFERROR(LEN(_xlfn.FORMULATEXT('XL-Test '!L49)),0) -> 14 | N48: {=INDIRECT(N47)} -> EC4|20-120C;1E-1AB2;20-10E3;7B-1D0272;17-A8C;39-184CAA;1B-3C61A;19-4068
...
